Workbook
Name AgendaStatusList: AgendaStatus[مستوى الإنجاز]
Name CompletionList: CompletionPercent[نسب الإنجاز]
Name DashboardDepartments: _xlfn.ANCHORARRAY(Logic!$B$7)
Name DashboardSectors: _xlfn.ANCHORARRAY(Logic!$A$7)
Name DepartmentsList: Departments[الوحدة التنظيمية]
Name EntitiesList: Entities[الجهة المعنية]
Name FollowUpList: FollowUp[متطلبات المتابعة]
Name FrequencyList: Frequency[دورية القياس]
Name IssuersList: Issuers[الجهة المسؤولة / صادر عن]
Name MonthsList: Months[الشهر]
Name OperationalObjectivesList: OperationalObjectives[الهدف التشغيلي]
Name PlanStatusList: PlanStatus[ضمن خطة دبي أو أجنداتها]
Name QuartersList: Quarters[الربع]
Name SectorsList: Sectors[القطاع]
Name StrategicObjectivesList: StrategicObjectives[الهدف الاستراتيجي]
Name TopicTypesList: TopicTypes[تصنيف الموضوع]
Name ValidationDate: Logic!$B$1
Name WorkStatusList: WorkStatus[مستوى الإنجاز]
Name YearsList: Years[الأعوام]
Name YesNoList: YesNo[القيمة]
Name AgendaStatusList: AgendaStatus[مستوى الإنجاز]
Name CompletionList: CompletionPercent[نسب الإنجاز]
Name DepartmentsList: Departments[الوحدة التنظيمية]
Name EntitiesList: Entities[الجهة المعنية]
Name FollowUpList: FollowUp[متطلبات المتابعة]
Name FrequencyList: Frequency[دورية القياس]
Name IssuersList: Issuers[الجهة المسؤولة / صادر عن]
Name MonthsList: Months[الشهر]
Name OperationalObjectivesList: OperationalObjectives[الهدف التشغيلي]
Name PlanStatusList: PlanStatus[ضمن خطة دبي أو أجنداتها]
Name QuartersList: Quarters[الربع]
Name SectorsList: Sectors[القطاع]
Name StrategicObjectivesList: StrategicObjectives[الهدف الاستراتيجي]
Name TopicTypesList: TopicTypes[تصنيف الموضوع]
Name WorkStatusList: WorkStatus[مستوى الإنجاز]
Name YearsList: Years[الأعوام]
Name YesNoList: YesNo[القيمة]

Sheet Idea
B2: تصميم مصفوفة شمولية (بانورامية) لتطوير جوانب العمل الحالية المتجزئة، وتصميم الروابط عبر مختلف مجالات العمل بما يخدم منظومة الأداء.

Sheet List of Values
A1: القطاع | B1: الجهة المعنية | D1: القطاع | F1: القطاع | G1: الوحدة التنظيمية | I1: دورية القياس | K1: الربع | M1: الشهر | O1: الأعوام | Q1: تصنيف الموضوع | S1: الجهة المسؤولة / صادر عن | U1: مستوى الإنجاز | W1: مستوى الإنجاز | Y1: نسب الإنجاز | AA1: ضمن خطة دبي أو أجنداتها | AC1: القيمة | AE1: متطلبات المتابعة | AG1: الهدف الاستراتيجي | AI1: الهدف الاستراتيجي | AJ1: الهدف التشغيلي | AL1: مستوى الإنجاز | AN1: نوع | AP1: أولوية | AR1: الإصدار | AT1: الحالة | AV1: مؤشرات الأداء
A2: التنمية المستدامة | B2: الإدارة العامة للإقامة وشؤون الأجانب - دبي | D2: الأمانة العامة للمجلس التنفيذي | F2: الأمانة العامة للمجلس التنفيذي | G2: مكتب الأمين العام | I2: ربع سنوي | K2: الربع الأول | M2: يناير | O2: 2015 | Q2: الأجندة السنوية | S2: المجلس التنفيذي | U2: متأخر | W2: متأخر | Y2: 0 | AA2: ضمن الخطة | AC2: نعم | AE2: مغلق (لا يتطلب متابعة) | AG2: توليد فرص المشاركة والدمج لجميع الفئات | AI2: توليد فرص المشاركة والدمج لجميع الفئات | AJ2: تعزيز الشراكة والعلاقات مع المعنيين | AL2: Cancelled | AN2: Strategic | AP2: H | AR2: محلي | AT2: قيد المراجعة | AV2: قيد الإجراء
A3: الحوكمة | B3: الأمانة العامة للمجلس التنفيذي | D3: الحوكمة | F3: الأمانة العامة للمجلس التنفيذي | G3: الشراكات والعلاقات الدولية | I3: نصف سنوي | K3: الربع الثاني | M3: فبراير | O3: 2016 | Q3: مستجد | S3: مجلس الشؤون الاستراتيجية | U3: جاهز للعرض | W3: قيد المراجعة | Y3: 0.05 | AA3: للإضافة | AC3: لا | AE3: رسالة رسمية | AG3: تعزيز مكانة الأمانة ككيان محوري في مركز الحكومة | AI3: توليد فرص المشاركة والدمج لجميع الفئات | AJ3: تعزيز كفاءة وفاعلية التواصل | AL3: Frozen | AN3: Operational | AP3: M | AR3: اتحادي | AT3: قيد الاعتماد | AV3: في الموعد
A4: التنمية المستدامة | B4: القيادة العامة لشرطة دبي | D4: التنمية المستدامة | F4: الأمانة العامة للمجلس التنفيذي | G4: مكتب التدقيق الداخلي | I4: سنوي | K4: الربع الثالث | M4: مارس | O4: 2017 | S4: الأمانة العامة للمجلس التنفيذي | U4: قيد المراجعة | W4: قيد التطوير | Y4: 0.1 | AA4: خارج الخطة | AE4: بريد من الوحدة التنظيمية | AG4: تحقيق التميز والريادة في الأداء والخدمات | AI4: تعزيز مكانة الأمانة ككيان محوري في مركز الحكومة | AJ4: الارتقاء بالنتائج لتحقيق الميزة الريادية لدبي | AL4: Not Started | AP4: L | AT4: مغلق
A5: التنمية المستدامة | B5: القيادة العامة للدفاع المدني - دبي | D5: الاقتصاد والتنمية الاجتماعية | F5: الأمانة العامة للمجلس التنفيذي | G5: مكتب خطة دبي | K5: الربع الرابع | M5: أبريل | O5: 2018 | U5: قيد التطوير | W5: منجز | Y5: 0.15 | AA5: لا ينطبق | AE5: ملغي | AG5: تعزيز التنسيق الداخلي والابتكار والمعرفة | AI5: تعزيز مكانة الأمانة ككيان محوري في مركز الحكومة | AJ5: ضمان توفر الأجندة السنوية للمجلس التنفيذي ومجلس الشؤون الاستراتيجية | AL5: Active | AT5: معلق
A6: التنمية المستدامة | B6: اللجنة العليا للتخطيط الحضري | D6: التميز والخدمات الحكومية | F6: الأمانة العامة للمجلس التنفيذي | G6: الأبحاث والرصد | M6: مايو | O6: 2019 | U6: منجز | Y6: 0.2 | AI6: تعزيز مكانة الأمانة ككيان محوري في مركز الحكومة | AJ6: تعزيز التوافق لنماذج العمل والسياسات والاستراتيجيات والأطر التنظيمية للحكومة | AL6: Completed
A7: التنمية المستدامة | B7: اللجنة العليا للتشريعات في إمارة دبي | D7: الاتصال الحكومي وشؤون الأمانة العامة | F7: الحوكمة | G7: الحوكمة | M7: يونيو | O7: 2020 | Y7: 0.25 | AI7: تحقيق التميز والريادة في الأداء والخدمات | AJ7: تقييم وتقرير مستوى التميز في الأداء والخدمات | AL7: Transferred
A8: التنمية المستدامة | B8: المجلس الأعلى للطاقة | F8: الحوكمة | G8: التشريعات الحكومية | M8: يوليو | O8: 2021 | Y8: 0.3 | AI8: تحقيق التميز والريادة في الأداء والخدمات | AJ8: تطوير وتمكين التميز في الأداء والخدمات الحكومية
A9: التنمية المستدامة | B9: المكتب الإعلامي لحكومة دبي | F9: الحوكمة | G9: التنفيذ والأداء | M9: أغسطس | O9: 2022 | Y9: 0.35 | AI9: تعزيز التنسيق الداخلي والابتكار والمعرفة | AJ9: تحقيق التميز في الأداء والخدمات المؤسسية
A10: التنمية المستدامة | B10: النيابة العامة | F10: التنمية المستدامة | G10: السياسات والاستراتيجيات الصحية والعدل | M10: سبتمبر | O10: 2023 | Y10: 0.4 | AI10: تعزيز التنسيق الداخلي والابتكار والمعرفة | AJ10: تعزيز ثقافة التعاون والعمل المشترك
A11: التنمية المستدامة | B11: بلدية دبي | F11: التنمية المستدامة | G11: السياسات والاستراتيجيات البيئية والبنية التحتية | M11: أكتوبر | O11: 2024 | Y11: 0.45 | AI11: تعزيز التنسيق الداخلي والابتكار والمعرفة | AJ11: توفير بيئة عمل محفزة وسعيدة
A12: التنمية المستدامة | B12: جمارك دبي | F12: الاقتصاد والتنمية الاجتماعية | G12: السياسات والإستراتيجيات الاجتماعية | M12: نوفمبر | O12: 2025 | Y12: 0.5 | AI12: تعزيز التنسيق الداخلي والابتكار والمعرفة | AJ12: ترسيخ ثقافة التشارك المعرفي والجاهزية للمستقبل
A13: التنمية المستدامة | B13: جهاز أمن الدولة بدبي | F13: الاقتصاد والتنمية الاجتماعية | G13: السياسات والإستراتيجيات الاقتصادية | M13: ديسمبر | O13: 2026 | Y13: 0.55
A14: الحوكمة | B14: جهاز الرقابة المالية | F14: التميز والخدمات الحكومية | G14: التقييم والدراسات | O14: 2027 | Y14: 0.6
A15: التنمية المستدامة | B15: دائرة الأراضي والأملاك | F15: التميز والخدمات الحكومية | G15: التميز والخدمات الحكومية | O15: 2028 | Y15: 0.65
A16: الاقتصاد والتنمية الاجتماعية | B16: دائرة الاقتصاد والسياحة بدبي | F16: الاتصال الحكومي وشؤون الأمانة العامة | G16: الاتصال الحكومي | O16: 2029 | Y16: 0.7
A17: الاقتصاد والتنمية الاجتماعية | B17: دائرة الشؤون الإسلامية والعمل الخيري | F17: الاتصال الحكومي وشؤون الأمانة العامة | G17: الاتصال الداخلي | O17: 2030 | Y17: 0.75
A18: التنمية المستدامة | B18: دائرة الشؤون القانونية لحكومة دبي | F18: الاتصال الحكومي وشؤون الأمانة العامة | G18: الخدمات المؤسسية | O18: 2031 | Y18: 0.8
A19: الحوكمة | B19: دائرة المالية | F19: الاتصال الحكومي وشؤون الأمانة العامة | G19: تميز الموارد البشرية | O19: 2032 | Y19: 0.85
A20: الحوكمة | B20: دائرة الموارد البشرية لحكومة دبي | F20: الاتصال الحكومي وشؤون الأمانة العامة | G20: المشتريات والشؤون الإدارية | O20: 2033 | Y20: 0.9
A21: الاقتصاد والتنمية الاجتماعية | B21: سلطة مركز دبي المالي العالمي | F21: الاتصال الحكومي وشؤون الأمانة العامة | G21: تقنية المعلومات | O21: 2034 | Y21: 0.95
A22: الاقتصاد والتنمية الاجتماعية | B22: مجلس تنمية الموارد البشرية الإماراتية | F22: الاتصال الحكومي وشؤون الأمانة العامة | G22: المالية والحسابات | O22: 2035 | Y22: 1
A23: الاقتصاد والتنمية الاجتماعية | B23: مجلس دبي الرياضي | F23: الاتصال الحكومي وشؤون الأمانة العامة | G23: المراسلات والأرشفة | O23: 2036
A24: الاقتصاد والتنمية الاجتماعية | B24: مجلس المناطق الحرة في إمارة دبي | F24: الاتصال الحكومي وشؤون الأمانة العامة | G24: تنفيذ ومتابعة المشاريع الميدانية | O24: 2037
A25: التنمية المستدامة | B25: محاكم دبي | O25: 2038
A26: التنمية المستدامة | B26: محاكم مركز دبي المالي العالمي | O26: 2039
A27: التنمية المستدامة | B27: مركز إرادة للعلاج والتأهيل في دبي | O27: 2040
A28: التنمية المستدامة | B28: مركز الإمارات العالمي للاعتماد
A29: التنمية المستدامة | B29: مركز دبي للأمن الإلكتروني
A30: التنمية المستدامة | B30: مركز دبي للأمن الاقتصادي
A31: الاقتصاد والتنمية الاجتماعية | B31: مركز دبي المالي العالمي
A32: التنمية المستدامة | B32: مركز دبي للمرونة
A33: التنمية المستدامة | B33: مؤسسة الاتصالات المتخصصة (نداء)
A34: الاقتصاد والتنمية الاجتماعية | B34: مؤسسة الأوقاف وإدارة أموال القُصّر في دبي
A35: التنمية المستدامة | B35: مؤسسة الموانئ والجمارك والمنطقة الحرة
A36: التنمية المستدامة | B36: مؤسسة دبي الصحية
A37: التنمية المستدامة | B37: مؤسسة دبي لخدمات الإسعاف
A38: الاقتصاد والتنمية الاجتماعية | B38: مؤسسة دبي للمستقبل
A39: التنمية المستدامة | B39: مؤسسة دبي للمطارات
... A53: الحوكمة | B53: مكتب سمو نائب حاكم دبي نائب رئيس مجلس الوزراء وزير المالية

Sheet Search
F2: Performance Search (Enter any part of the text Below)
W3: {=SUMPRODUCT( (--(Legislations[Late KPI]="متأخر")) * (IF($A$3="", 1, --(Legislations[القطاع]=$A$3))) * (IF($B$3="", 1, --(Legislations[الإدارة]=$B$3))) )}
B10: =IF(TRIM($F$8)="","",_xlfn.LET(_xlpm.n,ROWS(_xlfn.ANCHORARRAY(B11))-1,IF(_xlpm.n=0,"عدد البيانات 0",IF(INDEX(_xlfn.ANCHORARRAY(B11),2,1)="No matching results","عدد البيانات 0","عدد البيانات "&_xlpm.n))))
B11: {=IF(TRIM($F$8)="","",_xlfn.LET( _xlpm.q,TRIM($F$8), _xlpm.nl,CHAR(10), _xlpm.txt,_xlfn.LAMBDA(_xlpm.v,IF(_xlpm.v="","",_xlpm.v&"")), _xlpm.add,_xlfn.LAMBDA(_xlpm.v,IF(_xlpm.v="","",_xlpm.nl&_xlpm.v)), _xlpm.dt,_xlfn.LAMBDA(_xlpm.v,IF((_xlpm.v="")+(_xlpm.v=0),"",IF(ISNUMBER(_xlpm.v),TEXT(_xlpm.v,"dd/mm/yyyy"),_xlpm.v))), _xlpm.pct,_xlfn.LAMBDA(_xlpm.v,IF(_xlpm.v="","",IF(ISNUMBER(_xlpm.v),TEXT(_xlpm.v,"0.0%"),_xlpm.v))), _xlpm.num,_xlfn.LAMBDA(_xlpm.v,IF(_xlpm.v="","",IF(ISNUMBER(_xlpm.v),TEXT(_xlpm.v,"#,##0.00"),_xlpm.v))), _xlpm.owner,_xlfn.LAMBDA(_xlpm.v,IF(_xlpm.v="","غير مسجل",_xlpm.v&"")), _xlpm.org,_xlfn.LAMBDA(_xlpm.entity,_xlpm.dept,_xlpm.sector,_xlpm.txt(_xlpm.entity)&_xlpm.add(_xlpm.dept)&_xlpm.add(_xlpm.sector)), _xlpm.progress,_xlfn.LAMBDA(_xlpm.status,_xlpm.v,_xlpm.txt(_xlpm.status)&_xlpm.add(_xlpm.pct(_xlpm.v))), _xlpm.measured,_xlfn.LAMBDA(_xlpm.numer,_xlpm.denom,_xlpm.result, IF(ISNUMBER(_xlpm.numer)*ISNUMBER(_xlpm.denom)*(_xlpm.denom<>0),_xlpm.pct(_xlpm.result),"")), _xlpm.agendaTitle,ECSAC[[الموضوع ]], _xlpm.agendaData,_xlfn.HSTACK( IF(_xlpm.agendaTitle<>"","الأجندة السنوية",""), _xlpm.txt(_xlpm.agendaTitle)&_xlpm.add(ECSAC[تصنيف الموضوع]), _xlpm.txt(ECSAC[مستوى الإنجاز]), TRIM(_xlpm.txt(ECSAC[شهر الإنجاز])&" "&_xlpm.txt(ECSAC[سنة الإنجاز]))& _xlpm.add(ECSAC[الموعد الجديد إن وجد (شهر)]), _xlpm.owner(ECSAC[منسق الأمانة العامة]), _xlpm.org(ECSAC[الجهة المعنية],ECSAC[الإدارة],ECSAC[القطاع]), _xlpm.txt(ECSAC[ملاحظات فريق الأمانة العامة])& _xlpm.add(_xlpm.dt(ECSAC[تاريخ العرض على مجلس الشؤون]))& _xlpm.add(_xlpm.dt(ECSAC[تاريخ العرض على المجلس التنفيذي]))& _xlpm.add(ECSAC[ملاحظات مقرر المجالس]), _xlpm.txt(_xlpm.agendaTitle), IF(_xlpm.agendaTitle<>"","Annual Agenda","") ), _xlpm.decisionTitle,Resolutions[الموضوع], _xlpm.decisionData,_xlfn.HSTACK( IF(_xlpm.decisionTitle<>"","قرارات المجالس",""), _xlpm.txt(_xlpm.decisionTitle)& _xlpm.add(Resolutions[رقم القرار])& _xlpm.add(Resolutions[صادر عن]), _xlpm.progress(Resolutions[مستوى الإنجاز],Resolutions[نسبه الإنجاز]), _xlpm.dt(Resolutions[تاريخ الاجتماع]), _xlpm.owner(Resolutions[منسق الأمانة العامة]), _xlpm.org(Resolutions[الجهة المعنية],Resolutions[الإدارة],Resolutions[القطاع]), _xlpm.txt(Resolutions[متطلبات المتابعة])& _xlpm.add(_xlpm.dt(Resolutions[تاريخ إصدار خطاب المتابعة]))& _xlpm.add(_xlpm.dt(Resolutions[تاريخ الرد]))& _xlpm.add(Resolutions[ملاحظات]), _xlpm.txt(_xlpm.decisionTitle), "Decisions "&Resolutions[القرار الأخير] ), _xlpm.legislationTitle,Legislations[[عنوان التشريع ]], _xlpm.legislationData,_xlfn.HSTACK( IF(_xlpm.legislationTitle<>"","التشريعات",""), _xlpm.txt(_xlpm.legislationTitle)& _xlpm.add(Legislations[الرقم MCMS])& _xlpm.add(Legislations[طبيعة التشريع]), _xlpm.txt(Legislations[[الحالة ]])& IF(Legislations[تجاوز الموعد]="متأخر",_xlpm.nl&"تجاوز الموعد","")& IF(Legislations[Late KPI]="متأخر",_xlpm.nl&"متأخر وفق تاريخ التحقق",""), _xlpm.dt(Legislations[التاريخ المحدد من إدارة التشريعات])& _xlpm.add(_xlpm.dt(Legislations[تاريخ الإنجاز وفق (SLC) ]))& _xlpm.add(_xlpm.dt(Legislations[تمديد حتى])), IF(_xlpm.legislationTitle<>"","غير مسجل",""), _xlpm.org(Legislations[[الجهة المرسلة ]],Legislations[الإدارة],Legislations[القطاع]), _xlpm.txt(Legislations[[مرحلة التشريع ]])& _xlpm.add(Legislations[[مستجدات ]]), _xlpm.txt(_xlpm.legislationTitle), "Legislation "&Legislations[مؤشرات الأداء] ), _xlpm.specialTitle,Special[اسم المشروع], _xlpm.specialData,_xlfn.HSTACK( IF(_xlpm.specialTitle<>"","المشاريع الخاصة",""), _xlpm.txt(_xlpm.specialTitle)&_xlpm.add(Special[مشاريع سموه]), _xlpm.progress(Special[مستوى الإنجاز],Special[نسبة الإنجاز]), TRIM( _xlpm.txt(Special[انتهاء المشروع (الشهر)])&" "& _xlpm.txt(Special[انتهاء المشروع (السنة)])), _xlpm.owner(Special[مدير المشروع]), _xlpm.org(Special[الجهة المعنية],Special[[الإدارة ]],Special[القطاع]), _xlpm.txt(Special[المنجز للآن])& _xlpm.add(Special[المخطط في المرحلة المقبلة])& _xlpm.add(Special[ملاحظات مدير المشروع])& _xlpm.add(Special[توصيات إدارة الأداء والتنفيذ]), _xlpm.txt(_xlpm.specialTitle), "Special Projects "&Special[نبذة حول المشروع] ), _xlpm.projectTitle,Projects[اسم المشروع], _xlpm.projectData,_xlfn.HSTACK( IF(_xlpm.projectTitle<>"","مشاريع بموازنة إستراتيجية",""), _xlpm.txt(_xlpm.projectTitle)&_xlpm.add(Projects['#])&_xlpm.add(Projects[نوع]), _xlpm.progress(Projects[مستوى الإنجاز],Projects[نسبة الإنجاز]), _xlpm.dt(Projects[انتهاء المشروع]), _xlpm.owner(Projects[مدير المشروع]), _xlpm.org("",Projects[[الإدارة ]],Projects[القطاع]), _xlpm.txt(Projects[أولوية])& _xlpm.add(Projects[ملاحظات مدير المشروع])& IF(Projects[الموازنة المعتمدة الجديدة]<>"", _xlpm.add(_xlpm.num(Projects[الموازنة المعتمدة الجديدة])), _xlpm.add(_xlpm.num(Projects[الموازنة المعتمدة])))& _xlpm.add(_xlpm.num(Projects[المخصص]))& _xlpm.add(_xlpm.num(Projects[المنفق الفعلي]))& _xlpm.add(Projects[ملاحظات المالية]), _xlpm.txt(_xlpm.projectTitle), "Corporate Projects Budget Projects "&Projects[نبذة حول المشروع] ), _xlpm.valOne,_xlpm.measured( Strategy[البسط Q1], Strategy[المقام Q1], Strategy[نتيجة Q1]), _xlpm.valTwo,_xlpm.measured( Strategy[البسط Q2], Strategy[المقام Q2], Strategy[نتيجة Q2]), _xlpm.valThree,_xlpm.measured( Strategy[البسط Q3], Strategy[المقام Q3], Strategy[نتيجة Q3]), _xlpm.valFour,_xlpm.measured( Strategy[البسط Q4], Strategy[المقام Q4], Strategy[نتيجة Q4]), _xlpm.periods,TRIM( IF(_xlpm.valOne<>"","Q1 ","")& IF(_xlpm.valTwo<>"","Q2 ","")& IF(_xlpm.valThree<>"","Q3 ","")& IF(_xlpm.valFour<>"","Q4","")), _xlpm.annualResult,Strategy[[نتيجة العام ]], _xlpm.annualActual,IF((_xlpm.periods="")+(_xlpm.annualResult=""),"—",_xlpm.pct(_xlpm.annualResult)), _xlpm.annualTarget,IF(Strategy[المستهدف للعام]="","—", _xlpm.pct(Strategy[المستهدف للعام])), _xlpm.kpiTitle,Strategy[المؤشر], _xlpm.kpiData,_xlfn.HSTACK( IF(_xlpm.kpiTitle<>"","المؤشرات",""), _xlpm.txt(_xlpm.kpiTitle)&_xlpm.add(Strategy[الهدف الاستراتيجي]), IF(_xlpm.periods="","لم يقس بعد","تتوفر نتائج قياس"), _xlpm.txt(Strategy[دورية القياس])&_xlpm.add(_xlpm.periods), _xlpm.owner(Strategy[ملاك الهدف]), _xlpm.org("",Strategy[الإدارة],Strategy[القطاع]), _xlpm.annualActual&" / "&_xlpm.annualTarget& _xlpm.add(IF(_xlpm.valOne="","","Q1 "&_xlpm.valOne))& _xlpm.add(IF(_xlpm.valTwo="","","Q2 "&_xlpm.valTwo))& _xlpm.add(IF(_xlpm.valThree="","","Q3 "&_xlpm.valThree))& _xlpm.add(IF(_xlpm.valFour="","","Q4 "&_xlpm.valFour))& _xlpm.add(Strategy[ملاحظات]), _xlpm.txt(_xlpm.kpiTitle), "Indicators KPIs "&Strategy[الأهداف التشغيلية] ), _xlpm.allData,_xlfn.VSTACK( _xlpm.agendaData, _xlpm.decisionData, _xlpm.legislationData, _xlpm.specialData, _xlpm.projectData, _xlpm.kpiData ), _xlpm.rawVisible,_xlfn.CHOOSECOLS(_xlpm.allData,1,2,3,4,5,6,7), _xlpm.visibleData,IF( LEFT(_xlpm.rawVisible,1)=_xlpm.nl, MID(_xlpm.rawVisible,2,32767), _xlpm.rawVisible ), _xlpm.itemName,_xlfn.CHOOSECOLS(_xlpm.allData,8), _xlpm.searchData,_xlfn.BYROW( _xlpm.allData, _xlfn.LAMBDA(_xlpm.rowData,_xlfn.TEXTJOIN(" ",TRUE,_xlpm.rowData)) ), _xlpm.needle,SUBSTITUTE( SUBSTITUTE( SUBSTITUTE(_xlpm.q,"~","~~"), "*","~*"), "?","~?"), _xlpm.headers,_xlfn.HSTACK( "المصدر", "الموضوع / المشروع", "الحالة", "الموعد", "المسؤول", "الجهة / الوحدة", "آخر مستجد / الخطوة المقبلة" ), _xlfn.VSTACK( _xlpm.headers, _xlfn._xlws.FILTER( _xlpm.visibleData, (_xlpm.itemName<>"")* IF( OR(_xlpm.q="all",_xlpm.q="الكل"), TRUE, ISNUMBER(SEARCH(_xlpm.needle,_xlpm.searchData)) ), _xlfn.HSTACK("No matching results","","","","","","") ) ) ))}

Sheet Performance
B2: ="التقرير الشهري للأداء والتنفيذ - حتى تاريخ "&TEXT(Logic!B1,"dd/mm/yyyy") | AY2: =IF(BY4 >BO4,1,"") | AZ2: استراتيجية الأمانة العامة | BE2: الإجمالي / المؤشرات المقاسة | BO2: متوسط النتائج المقاسة | BY2: متوسط المستهدفات المعتمدة
BE4: =IF(Logic!AQ3="","-",Logic!AQ3) | BO4: =IF(Logic!AR3="","-",Logic!AR3) | BY4: =IF(Logic!AS3="","-",Logic!AS3)
B5: القطاع | X5: الوحدة التنظيمية
BE6: =IFERROR(IF(Logic!AX4="","",Logic!AX4),"") | BO6: =IFERROR(IF(Logic!AY4="","",Logic!AY4),"")
B8: محافظ المتابعة التنفيذية | AS8: محفظة المشاريع
AU10: المشاريع الخاصة
C11: =IF(Performance!W13=0,"",1) | D11: الأجندة السنوية | K11: المجموع | P11: =IFERROR(IF(Logic!BZ4="","",Logic!BZ4),"") | W11: متأخر | AB11: منجز | AG11: جاهز للعرض | AL11: قيد العمل | BK11: =IF(AU14<>SUM(AZ14,BR14), "نقص في البيانات", "")
P12: =IF(Logic!E3="","",Logic!E3) | AT12: =IF(SUM(BD14,BV14)>0,1,"") | AU12: المجموع | AZ12: للقيادة | BD12: متأخر | BH12: منجز | BL12: قيد العمل | BR12: للأمانة العامة | BV12: متأخر | BZ12: منجز | CD12: قيد العمل
K13: =IF(Logic!D3="","",Logic!D3) | P13: من الأجندة | W13: =IF(Logic!J3="","",Logic!J3) | AB13: =IF(Logic!I3="","",Logic!I3) | AG13: =IF(Logic!G3="","",Logic!G3) | AL13: =IF(Logic!H3="","",Logic!H3)
P14: ما يستجد | AU14: =IF(Logic!Y3="","",Logic!Y3) | AZ14: =IF(Logic!Z3="","",Logic!Z3) | BD14: =IF(Logic!AB3="","",Logic!AB3) | BH14: =IF(Logic!AA3="","",Logic!AA3) | BL14: =AZ14-SUM(BD14:BK17) | BR14: =IF(Logic!AC3="","",Logic!AC3) | BV14: =IF(Logic!AE3="","",Logic!AE3) | BZ14: =IF(Logic!AD3="","",Logic!AD3) | CD14: =BR14-SUM(BV14:CC17)
P15: =IF(Logic!F3="","",Logic!F3)
D16: =IF( OR( K13<>SUM(P12,P15), K13<>SUM(AL13,AG13,AB13,W13) ), "نقص في البيانات", "" ) | K16: =IFERROR(IF(Logic!BE4="","",Logic!BE4),"") | P16: =IFERROR(IF(Logic!CA4="","",Logic!CA4),"") | W16: =IFERROR(IF(Logic!BG4="","",Logic!BG4),"") | AB16: =IFERROR(IF(Logic!BF4="","",Logic!BF4),"") | AG16: =IFERROR(IF(Logic!$CC$4="","",Logic!$CC$4),"") | AL16: =IFERROR(IF(Logic!$CB$4="","",Logic!$CB$4),"")
C18: =IF(Performance!S20=0,"",1) | D18: قرارات المجالس | K18: المجموع | S18: متأخر | AA18: منجز | AI18: قيد العمل | AU18: =IFERROR(IF(Logic!AZ4="","",Logic!AZ4),"") | AZ18: =IFERROR(IF(Logic!$BV$4="","",Logic!$BV$4),"") | BD18: =IFERROR(IF(Logic!BB4="","",Logic!BB4),"") | BH18: =IFERROR(IF(Logic!BA4="","",Logic!BA4),"") | BL18: =IFERROR(IF(Logic!$BX$4="","",Logic!$BX$4),"") | BR18: =IFERROR(IF(Logic!$BW$4="","",Logic!$BW$4),"") | BV18: =IFERROR(IF(Logic!BD4="","",Logic!BD4),"") | BZ18: =IFERROR(IF(Logic!BC4="","",Logic!BC4),"") | CD18: =IFERROR(IF(Logic!$BY$4="","",Logic!$BY$4),"")
AU19: مشاريع بموازنة استراتيجية
K20: =IF(Logic!L3="","",Logic!L3) | S20: =IF(Logic!O3="","",Logic!O3) | AA20: =IF(Logic!N3="","",Logic!N3) | AI20: =IF(Logic!M3="","",Logic!M3) | BK20: =IF(AU23<>SUM(BR23,BV23,BZ23,CD23), "نقص في البيانات", "") | BQ20: {="مشاريع "&YEAR(ValidationDate)&": "& SUM(Logic!$AL$3:$AO$3)& " | مشاريع "&(YEAR(ValidationDate)+1)&": "& SUMPRODUCT( --(Projects[اسم المشروع]<>"")* --ISNUMBER(Projects[انتهاء المشروع])* --(Projects[انتهاء المشروع]>=DATE(YEAR(ValidationDate)+1,1,1))* --(Projects[انتهاء المشروع]<DATE(YEAR(ValidationDate)+2,1,1))* IF( Logic!$A$3="", 1, --(Projects[القطاع]=Logic!$A$3) )* IF( Logic!$B$3="", 1, --(Projects[[الإدارة ]]=Logic!$B$3) ) )}
AT21: =IF(AZ23=0,"",1) | AU21: المجموع | AZ21: متأخر | BD21: منجز | BH21: قيد العمل | BL21: ملغى/معلق | BR21: ربع 1 | BV21: ربع 2 | BZ21: ربع 3 | CD21: ربع 4
D23: {=_xlfn.LET( _xlpm.tidy,_xlfn.LAMBDA(_xlpm.x, TRIM(SUBSTITUTE(IFERROR(_xlpm.x&"",""),CHAR(160)," ")) ), _xlpm.topic,IFERROR(Resolutions[الموضوع],""), _xlpm.followup,_xlpm.tidy(Resolutions[متطلبات المتابعة]), _xlpm.sector,_xlpm.tidy(Resolutions[القطاع]), _xlpm.dept,_xlpm.tidy(Resolutions[الإدارة]), _xlpm.selectedSector,_xlpm.tidy(Logic!$A$3), _xlpm.selectedDept,_xlpm.tidy(Logic!$B$3), _xlpm.scope, (_xlpm.topic<>"")* IF(_xlpm.selectedSector="",1,--(_xlpm.sector=_xlpm.selectedSector))* IF(_xlpm.selectedDept="",1,--(_xlpm.dept=_xlpm.selectedDept)), _xlpm.invalidFollowup, SUMPRODUCT( _xlpm.scope* --( ( (_xlpm.followup="")+ ISNA( _xlfn.XMATCH( _xlpm.followup, _xlpm.tidy(FollowUp[متطلبات المتابعة]) ) ) )>0 ) ), IF( OR( _xlpm.invalidFollowup>0, K20<>SUM(AI20,AA20,S20) ), "نقص في البيانات", "" ) )} | K23: =IFERROR(IF(Logic!BH4="","",Logic!BH4),"") | S23: =IFERROR(IF(Logic!BJ4="","",Logic!BJ4),"") | AA23: =IFERROR(IF(Logic!BI4="","",Logic!BI4),"") | AI23: =IFERROR(IF(Logic!$CD$4="","",Logic!$CD$4),"") | AU23: =IF(Logic!AG3="","",Logic!AG3) | AZ23: =IF(Logic!AK3="","",Logic!AK3) | BD23: =IF(Logic!AJ3="","",Logic!AJ3) | BH23: =IF(Logic!AH3="","",Logic!AH3) | BL23: =IF(Logic!AI3="","",Logic!AI3) | BR23: =IF(Logic!AL3="","",Logic!AL3) | BV23: =IF(Logic!AM3="","",Logic!AM3) | BZ23: =IF(Logic!AN3="","",Logic!AN3) | CD23: =IF(Logic!AO3="","",Logic!AO3)
C25: =IF(S27=0,"",1) | D25: التشريعات | K25: المجموع | S25: متأخر | Y25: منجز على الموعد تجاوز الموعد | AK25: قيد العمل
AU26: =IFERROR(IF(Logic!BK4="","",Logic!BK4),"") | AZ26: =IFERROR(IF(Logic!BM4="","",Logic!BM4),"") | BD26: =IFERROR(IF(Logic!BL4="","",Logic!BL4),"") | BH26: =IFERROR(IF(Logic!$CE$4="","",Logic!$CE$4),"") | BL26: =IFERROR(IF(Logic!$CF$4="","",Logic!$CF$4),"") | BR26: =IFERROR(IF(Logic!$CG$4="","",Logic!$CG$4),"") | BV26: =IFERROR(IF(Logic!$CH$4="","",Logic!$CH$4),"") | BZ26: =IFERROR(IF(Logic!$CI$4="","",Logic!$CI$4),"") | CD26: =IFERROR(IF(Logic!$CJ$4="","",Logic!$CJ$4),"")
K27: =IF(Logic!S3="","",Logic!S3) | S27: =IF(Logic!W3="","", Logic!W3) | Y27: =IF(Logic!U3="","",Logic!U3) | AE27: =IF(Logic!V3="","",Logic!V3) | AK27: =IF(Logic!T3="","",Logic!T3) | AU27: الموازنة المعتمدة | BD27: =IF(Logic!AG6="","",Logic!AG6) | BL27: =IFERROR(IF(Logic!BR4="","",Logic!BR4),"") | BO27: المخصص | BX27: =IF(Logic!AI6="","",Logic!AI6) | CF27: =IFERROR(IF(Logic!$BT$4="","",Logic!$BT$4),"")
AU29: المنفق الفعلي | BD29: =IF(Logic!AH6="","",Logic!AH6) | BL29: =IFERROR(IF(Logic!BS4="","",Logic!BS4),"") | BO29: غير المخصص | BX29: =IF(Logic!AJ6="","",Logic!AJ6) | CF29: =IFERROR(IF(Logic!BU4="","",Logic!BU4),"")
D30: =IF(K27<>SUM(AK27,Y27,AE27),"نقص في البيانات","") | K30: =IFERROR(IF(Logic!BN4="","",Logic!BN4),"") | S30: =IFERROR(IF(Logic!BQ4="","",Logic!BQ4),"") | Y30: =IFERROR(IF(Logic!BO4="","",Logic!BO4),"") | AE30: =IFERROR(IF(Logic!BP4="","",Logic!BP4),"") | AK30: =IFERROR(_xlfn.LET(_xlpm.previous,Logic!$BN$2-Logic!$BO$2-Logic!$BP$2,_xlpm.current,$AK$27,_xlpm.change,_xlpm.current-_xlpm.previous,IF(OR(COUNT(Logic!$BN$2:$BP$2)<3,NOT(ISNUMBER(_xlpm.current)),_xlpm.previous<0,_xlpm.change=0),"",IF(_xlpm.change>0,"▲ +","▼ -")&TEXT(ABS(_xlpm.change),"#,##0"))),"")
B33: ملاحظات تفصيلية حول مواضيع تستدعي المتابعة:
B35: {=IFERROR(INDEX(_xlfn.ANCHORARRAY(Logic!$CL$2),ROWS($B$35:B35)),"")}
B36: {=IFERROR(INDEX(_xlfn.ANCHORARRAY(Logic!$CL$2),ROWS($B$35:B36)),"")}
B37: {=IFERROR(INDEX(_xlfn.ANCHORARRAY(Logic!$CL$2),ROWS($B$35:B37)),"")}
B38: {=IFERROR(INDEX(_xlfn.ANCHORARRAY(Logic!$CL$2),ROWS($B$35:B38)),"")}
B39: {=IFERROR(INDEX(_xlfn.ANCHORARRAY(Logic!$CL$2),ROWS($B$35:B39)),"")}
B40: {=IFERROR(INDEX(_xlfn.ANCHORARRAY(Logic!$CL$2),ROWS($B$35:B40)),"")}
B41: {=IFERROR(INDEX(_xlfn.ANCHORARRAY(Logic!$CL$2),ROWS($B$35:B41)),"")}
B42: {=IFERROR(INDEX(_xlfn.ANCHORARRAY(Logic!$CL$2),ROWS($B$35:B42)),"")}
B43: {=IFERROR(INDEX(_xlfn.ANCHORARRAY(Logic!$CL$2),ROWS($B$35:B43)),"")}
C45: إدارة التنفيذ والأداء، حقوق النشر © 2026 الأمانة العامة للمجلس التنفيذي لإمارة دبي - جميع الحقوق محفوظة

Sheet Logic
A1: Monthly Cutt-Off Date | B1: 46295 | D1: الأجندة | L1: القرارات | S1: التشريعات | Y1: المشاريع الخاصة لسموه | AC1: المشاريع الخاصة | AG1: المشاريع | AQ1: استراتيجية_الأمانة | AU1: القطاع | AV1: الوحدة التنظيمية | AW1: الحالة | AX1: المؤشرات_المقاسة | AY1: متوسط_النتائج | AZ1: الخاصة_المجموع | BA1: سموه_منجز | BB1: سموه_متأخر | BC1: الخاصة_منجز | BD1: الخاصة_متأخر | BE1: الأجندة_المجموع | BF1: الأجندة_منجز | BG1: الأجندة_متأخر | BH1: القرارات_المجموع | BI1: القرارات_منجز | BJ1: القرارات_متأخر | BK1: مشاريع_الأمانة_المجموع | BL1: مشاريع_الأمانة_منجز | BM1: مشاريع_الأمانة_متأخر | BN1: التشريعات_المجموع | BO1: التشريعات_منجز | BP1: التشريعات_تجاوز الموعد | BQ1: التشريعات_متأخر | BR1: الموازنة المعتمدة | BS1: المنفق الفعلي | BT1: المخصص | BU1: غير المخصص | BV1: سموه_المجموع | BW1: الخاصة_المجموع_للأمانة | BX1: سموه_قيد_العمل | BY1: الخاصة_قيد_العمل | BZ1: الأجندة_الأصلية | CA1: الأجندة_مستجد | CB1: الأجندة_قيد_العمل | CC1: الأجندة_جاهز_للعرض | CD1: القرارات_قيد_العمل | CE1: مشاريع_الأمانة_قيد_العمل | CF1: مشاريع_الأمانة_ملغي_معلق | CG1: مشاريع_الأمانة_Q1 | CH1: مشاريع_الأمانة_Q2 | CI1: مشاريع_الأمانة_Q3 | CJ1: مشاريع_الأمانة_Q4 | CL1: ملاحظات تفصيلية حول مواضيع تستدعي المتابعة:
D2: المجموع | E2: من الأجندة | F2: ما يستجد | G2: جاهز للعرض | H2: قيد العمل | I2: منجز | J2: متأخر | L2: مجموع القرارت | M2: قيد العمل | N2: منجز | O2: متأخر | P2: قيد التطوير | Q2: قيد المراجعة | S2: المجموع | T2: قيد المراجعه | U2: منجز على الموعد | V2: تجاوز الموعد | W2: متأخر | Y2: المجموع | Z2: لسموه | AA2: منجز | AB2: متأخر | AC2: خاصة | AD2: منجز | AE2: متأخر | AG2: المجموع | AH2: قيد العمل | AI2: ملغي/معلق | AJ2: منجز | AK2: متأخر | AL2: ربع 1 | AM2: ربع 2 | AN2: ربع 3 | AO2: ربع 4 | AQ2: المجموع | AR2: متوسط النتائج المقاسة | AS2: متوسط المستهدفات المعتمدة | AW2: الشهر السابق | AX2: {=SUMPRODUCT( $AX$5:$AX$31* IF($A$3="",1,--($AU$5:$AU$31=$A$3))* IF($B$3="",1,--($AV$5:$AV$31=$B$3)) )} | AY2: {=IFERROR( _xlfn.LET( _xlpm.weights,$AX$5:$AX$31, _xlpm.results,$AY$5:$AY$31, _xlpm.sectors,$AU$5:$AU$31, _xlpm.units,$AV$5:$AV$31, _xlpm.include, ISNUMBER(_xlpm.results)* (_xlpm.weights>0)* IF($A$3="",1,--(_xlpm.sectors=$A$3))* IF($B$3="",1,--(_xlpm.units=$B$3)), _xlpm.selectedWeights,_xlfn._xlws.FILTER(_xlpm.weights,_xlpm.include), _xlpm.selectedResults,_xlfn._xlws.FILTER(_xlpm.results,_xlpm.include), SUMPRODUCT(_xlpm.selectedWeights,_xlpm.selectedResults)/ SUM(_xlpm.selectedWeights) ), "" )} | AZ2: {=SUMPRODUCT( AZ$5:AZ$31* IF($A$3="",1,--($AU$5:$AU$31=$A$3))* IF($B$3="",1,--($AV$5:$AV$31=$B$3)) )} | BA2: {=SUMPRODUCT( BA$5:BA$31* IF($A$3="",1,--($AU$5:$AU$31=$A$3))* IF($B$3="",1,--($AV$5:$AV$31=$B$3)) )} | BB2: {=SUMPRODUCT( BB$5:BB$31* IF($A$3="",1,--($AU$5:$AU$31=$A$3))* IF($B$3="",1,--($AV$5:$AV$31=$B$3)) )} | BC2: {=SUMPRODUCT( BC$5:BC$31* IF($A$3="",1,--($AU$5:$AU$31=$A$3))* IF($B$3="",1,--($AV$5:$AV$31=$B$3)) )} | BD2: {=SUMPRODUCT( BD$5:BD$31* IF($A$3="",1,--($AU$5:$AU$31=$A$3))* IF($B$3="",1,--($AV$5:$AV$31=$B$3)) )} | BE2: {=SUMPRODUCT( BE$5:BE$31* IF($A$3="",1,--($AU$5:$AU$31=$A$3))* IF($B$3="",1,--($AV$5:$AV$31=$B$3)) )} | BF2: {=SUMPRODUCT( BF$5:BF$31* IF($A$3="",1,--($AU$5:$AU$31=$A$3))* IF($B$3="",1,--($AV$5:$AV$31=$B$3)) )} | BG2: {=SUMPRODUCT( BG$5:BG$31* IF($A$3="",1,--($AU$5:$AU$31=$A$3))* IF($B$3="",1,--($AV$5:$AV$31=$B$3)) )} | ... CJ2: {=SUMPRODUCT( CJ$5:CJ$31* IF($A$3="",1,--($AU$5:$AU$31=$A$3))* IF($B$3="",1,--($AV$5:$AV$31=$B$3)) )} | CL2: {=_xlfn.LET( _xlpm.sector,$A$3, _xlpm.dept,$B$3, _xlpm.tidy,_xlfn.LAMBDA(_xlpm.x, TRIM( SUBSTITUTE( SUBSTITUTE( SUBSTITUTE(_xlpm.x,CHAR(160)," "), CHAR(10)," "), CHAR(13)," ") ) ), _xlpm.mkline,_xlfn.LAMBDA(_xlpm.src,_xlpm.department,_xlpm.sourceSector,_xlpm.topic,_xlpm.status,_xlpm.update, _xlpm.src&" - "& _xlpm.tidy(_xlpm.status)&" - "& IF(_xlpm.tidy(_xlpm.department)="",_xlpm.tidy(_xlpm.sourceSector),_xlpm.tidy(_xlpm.department))& " - "&_xlpm.tidy(_xlpm.topic)& IF(_xlpm.tidy(_xlpm.update)="",""," - "&_xlpm.tidy(_xlpm.update)) ), _xlpm.special,_xlfn._xlws.FILTER( _xlpm.mkline( "المشاريع الخاصة", Special[[الإدارة ]], Special[القطاع], Special[اسم المشروع], Special[مستوى الإنجاز], Special[ملاحظات مدير المشروع] ), (Special[اسم المشروع]<>"")* ISNUMBER( _xlfn.XMATCH( Special[مستوى الإنجاز], {"متأخر","معلق","ملغى"} ) )* IF(_xlpm.sector="",1,--(Special[القطاع]=_xlpm.sector))* IF(_xlpm.dept="",1,--(Special[[الإدارة ]]=_xlpm.dept)), "" ), _xlpm.projects,_xlfn._xlws.FILTER( _xlpm.mkline( "مشاريع الأمانة", Projects[[الإدارة ]], Projects[القطاع], Projects[اسم المشروع], IF( Projects[مستوى الإنجاز]="Cancelled", "ملغى", IF( Projects[مستوى الإنجاز]="Frozen", "معلق", IF( Projects[مستوى الإنجاز]="Transferred", "منقول", "متأخر" ) ) ), Projects[ملاحظات مدير المشروع] ), (Projects[اسم المشروع]<>"")* ( ( (Projects[Late KPI]="Late")+ (Projects[مستوى الإنجاز]="Frozen")+ (Projects[مستوى الإنجاز]="Cancelled")+ (Projects[مستوى الإنجاز]="Transferred") )>0 )* IF(_xlpm.sector="",1,--(Projects[القطاع]=_xlpm.sector))* IF(_xlpm.dept="",1,--(Projects[[الإدارة ]]=_xlpm.dept)), "" ), _xlpm.agenda,_xlfn._xlws.FILTER( _xlpm.mkline( "الأجندة السنوية", ECSAC[الإدارة], ECSAC[القطاع], ECSAC[[الموضوع ]], ECSAC[مستوى الإنجاز], ECSAC[ملاحظات فريق الأمانة العامة] ), (ECSAC[[الموضوع ]]<>"")* ISNUMBER( _xlfn.XMATCH( ECSAC[مستوى الإنجاز], {"متأخر","معلق","ملغى"} ) )* IF(_xlpm.sector="",1,--(ECSAC[القطاع]=_xlpm.sector))* IF(_xlpm.dept="",1,--(ECSAC[الإدارة]=_xlpm.dept)), "" ), _xlpm.decisions,_xlfn._xlws.FILTER( _xlpm.mkline( "القرارات", Resolutions[الإدارة], Resolutions[القطاع], Resolutions[الموضوع], Resolutions[مستوى الإنجاز], Resolutions[ملاحظات] ), (Resolutions[الموضوع]<>"")* ( ( (TRIM(SUBSTITUTE(Resolutions[متطلبات المتابعة],CHAR(160)," "))="رسالة رسمية")+ (TRIM(SUBSTITUTE(Resolutions[متطلبات المتابعة],CHAR(160)," "))="بريد من الوحدة التنظيمية") )>0 )* ISNUMBER( _xlfn.XMATCH( TRIM(SUBSTITUTE(Resolutions[مستوى الإنجاز],CHAR(160)," ")), {"متأخر","معلق","ملغى"} ) )* IF( _xlpm.sector="", 1, --( TRIM(SUBSTITUTE(Resolutions[القطاع],CHAR(160)," "))= TRIM(SUBSTITUTE(_xlpm.sector,CHAR(160)," ")) ) )* IF( _xlpm.dept="", 1, --( TRIM(SUBSTITUTE(Resolutions[الإدارة],CHAR(160)," "))= TRIM(SUBSTITUTE(_xlpm.dept,CHAR(160)," ")) ) ), "" ), _xlpm.laws,_xlfn._xlws.FILTER( _xlpm.mkline( "التشريعات", Legislations[الإدارة], Legislations[القطاع], Legislations[[عنوان التشريع ]], "متأخر", Legislations[[مستجدات ]] ), (Legislations[[عنوان التشريع ]]<>"")* (Legislations[Late KPI]="متأخر")* IF(_xlpm.sector="",1,--(Legislations[القطاع]=_xlpm.sector))* IF(_xlpm.dept="",1,--(Legislations[الإدارة]=_xlpm.dept)), "" ), _xlpm.items,_xlfn.VSTACK( _xlpm.special, _xlpm.projects, _xlpm.agenda, _xlpm.decisions, _xlpm.laws ), _xlpm.filtered,_xlfn._xlws.FILTER( _xlpm.items, _xlpm.items<>"", "" ), IF( _xlpm.filtered="", "لا توجد مواضيع تتطلب المتابعة", _xlfn.SEQUENCE(ROWS(_xlpm.filtered))&". "&_xlpm.filtered ) )}
A3: =IF(Performance!B6="","",Performance!B6) | B3: =IF(Performance!X6="","", Performance!X6) | D3: {=SUMPRODUCT( (--(ECSAC[[الموضوع ]]<>"")) * (IF($A$3="", 1, --(ECSAC[القطاع]=$A$3))) * (IF($B$3="", 1, --(ECSAC[الإدارة]=$B$3))) )} | E3: {=SUMPRODUCT( (--(ECSAC[تصنيف الموضوع]="الأجندة السنوية")) * (IF($A$3="", 1, --(ECSAC[القطاع]=$A$3))) * (IF($B$3="", 1, --(ECSAC[الإدارة]=$B$3))) )} | F3: {=SUMPRODUCT( (--(ECSAC[تصنيف الموضوع]="مستجد")) * (IF($A$3="",1,--(ECSAC[القطاع]=$A$3))) * (IF($B$3="",1,--(ECSAC[الإدارة]=$B$3))) )} | G3: {=SUMPRODUCT( (--(ECSAC[مستوى الإنجاز]="جاهز للعرض")) * (IF($A$3="", 1, --(ECSAC[القطاع]=$A$3))) * (IF($B$3="", 1, --(ECSAC[الإدارة]=$B$3))) )} | H3: {=SUMPRODUCT( --(((ECSAC[مستوى الإنجاز]="قيد التطوير")+ (ECSAC[مستوى الإنجاز]="قيد المراجعة"))>0)* IF($A$3="",1,--(ECSAC[القطاع]=$A$3))* IF($B$3="",1,--(ECSAC[الإدارة]=$B$3)) )} | I3: {=SUMPRODUCT( (--(ECSAC[مستوى الإنجاز]="منجز")) * (IF($A$3="", 1, --(ECSAC[القطاع]=$A$3))) * (IF($B$3="", 1, --(ECSAC[الإدارة]=$B$3))) )} | J3: {=SUMPRODUCT( (--(ECSAC[مستوى الإنجاز]="متأخر")) * (IF($A$3="", 1, --(ECSAC[القطاع]=$A$3))) * (IF($B$3="", 1, --(ECSAC[الإدارة]=$B$3))) )} | L3: {=_xlfn.LET( _xlpm.topic,IFERROR(Resolutions[الموضوع],""), _xlpm.followup,TRIM(SUBSTITUTE(IFERROR(Resolutions[متطلبات المتابعة],""),CHAR(160)," ")), _xlpm.sector,TRIM(SUBSTITUTE(IFERROR(Resolutions[القطاع],""),CHAR(160)," ")), _xlpm.dept,TRIM(SUBSTITUTE(IFERROR(Resolutions[الإدارة],""),CHAR(160)," ")), _xlpm.selectedSector,TRIM(SUBSTITUTE(IFERROR($A$3,""),CHAR(160)," ")), _xlpm.selectedDept,TRIM(SUBSTITUTE(IFERROR($B$3,""),CHAR(160)," ")), SUMPRODUCT( --(_xlpm.topic<>"")* --( ( (_xlpm.followup="رسالة رسمية")+ (_xlpm.followup="بريد من الوحدة التنظيمية") )>0 )* --(((_xlpm.selectedSector="")+(_xlpm.sector=_xlpm.selectedSector))>0)* --(((_xlpm.selectedDept="")+(_xlpm.dept=_xlpm.selectedDept))>0) ) )} | M3: =SUM(P3:Q3) | N3: {=_xlfn.LET( _xlpm.topic,IFERROR(Resolutions[الموضوع],""), _xlpm.followup,TRIM(SUBSTITUTE(IFERROR(Resolutions[متطلبات المتابعة],""),CHAR(160)," ")), _xlpm.status,TRIM(SUBSTITUTE(IFERROR(Resolutions[مستوى الإنجاز],""),CHAR(160)," ")), _xlpm.sector,TRIM(SUBSTITUTE(IFERROR(Resolutions[القطاع],""),CHAR(160)," ")), _xlpm.dept,TRIM(SUBSTITUTE(IFERROR(Resolutions[الإدارة],""),CHAR(160)," ")), _xlpm.selectedSector,TRIM(SUBSTITUTE(IFERROR($A$3,""),CHAR(160)," ")), _xlpm.selectedDept,TRIM(SUBSTITUTE(IFERROR($B$3,""),CHAR(160)," ")), SUMPRODUCT( --(_xlpm.topic<>"")* --( ( (_xlpm.followup="رسالة رسمية")+ (_xlpm.followup="بريد من الوحدة التنظيمية") )>0 )* --(_xlpm.status="منجز")* --(((_xlpm.selectedSector="")+(_xlpm.sector=_xlpm.selectedSector))>0)* --(((_xlpm.selectedDept="")+(_xlpm.dept=_xlpm.selectedDept))>0) ) )} | O3: {=_xlfn.LET( _xlpm.topic,IFERROR(Resolutions[الموضوع],""), _xlpm.followup,TRIM(SUBSTITUTE(IFERROR(Resolutions[متطلبات المتابعة],""),CHAR(160)," ")), _xlpm.status,TRIM(SUBSTITUTE(IFERROR(Resolutions[مستوى الإنجاز],""),CHAR(160)," ")), _xlpm.sector,TRIM(SUBSTITUTE(IFERROR(Resolutions[القطاع],""),CHAR(160)," ")), _xlpm.dept,TRIM(SUBSTITUTE(IFERROR(Resolutions[الإدارة],""),CHAR(160)," ")), _xlpm.selectedSector,TRIM(SUBSTITUTE(IFERROR($A$3,""),CHAR(160)," ")), _xlpm.selectedDept,TRIM(SUBSTITUTE(IFERROR($B$3,""),CHAR(160)," ")), SUMPRODUCT( --(_xlpm.topic<>"")* --( ( (_xlpm.followup="رسالة رسمية")+ (_xlpm.followup="بريد من الوحدة التنظيمية") )>0 )* --(_xlpm.status="متأخر")* --(((_xlpm.selectedSector="")+(_xlpm.sector=_xlpm.selectedSector))>0)* --(((_xlpm.selectedDept="")+(_xlpm.dept=_xlpm.selectedDept))>0) ) )} | P3: {=_xlfn.LET( _xlpm.topic,IFERROR(Resolutions[الموضوع],""), _xlpm.followup,TRIM(SUBSTITUTE(IFERROR(Resolutions[متطلبات المتابعة],""),CHAR(160)," ")), _xlpm.itemStatus,TRIM(SUBSTITUTE(IFERROR(Resolutions[مستوى الإنجاز],""),CHAR(160)," ")), _xlpm.sector,TRIM(SUBSTITUTE(IFERROR(Resolutions[القطاع],""),CHAR(160)," ")), _xlpm.dept,TRIM(SUBSTITUTE(IFERROR(Resolutions[الإدارة],""),CHAR(160)," ")), _xlpm.selSector,TRIM(SUBSTITUTE(IFERROR($A$3,""),CHAR(160)," ")), _xlpm.selDept,TRIM(SUBSTITUTE(IFERROR($B$3,""),CHAR(160)," ")), SUMPRODUCT( --(_xlpm.topic<>""), --(((_xlpm.followup="رسالة رسمية")+(_xlpm.followup="بريد من الوحدة التنظيمية"))>0), --(_xlpm.itemStatus="قيد التطوير"), --(((_xlpm.selSector="")+(_xlpm.sector=_xlpm.selSector))>0), --(((_xlpm.selDept="")+(_xlpm.dept=_xlpm.selDept))>0) ) )} | Q3: {=_xlfn.LET( _xlpm.topic,IFERROR(Resolutions[الموضوع],""), _xlpm.followup,TRIM(SUBSTITUTE(IFERROR(Resolutions[متطلبات المتابعة],""),CHAR(160)," ")), _xlpm.itemStatus,TRIM(SUBSTITUTE(IFERROR(Resolutions[مستوى الإنجاز],""),CHAR(160)," ")), _xlpm.sector,TRIM(SUBSTITUTE(IFERROR(Resolutions[القطاع],""),CHAR(160)," ")), _xlpm.dept,TRIM(SUBSTITUTE(IFERROR(Resolutions[الإدارة],""),CHAR(160)," ")), _xlpm.selSector,TRIM(SUBSTITUTE(IFERROR($A$3,""),CHAR(160)," ")), _xlpm.selDept,TRIM(SUBSTITUTE(IFERROR($B$3,""),CHAR(160)," ")), SUMPRODUCT( --(_xlpm.topic<>""), --(((_xlpm.followup="رسالة رسمية")+(_xlpm.followup="بريد من الوحدة التنظيمية"))>0), --(_xlpm.itemStatus="قيد المراجعة"), --(((_xlpm.selSector="")+(_xlpm.sector=_xlpm.selSector))>0), --(((_xlpm.selDept="")+(_xlpm.dept=_xlpm.selDept))>0) ) )} | S3: {=SUMPRODUCT( (--(Legislations[[عنوان التشريع ]]<>"")) * (IF($A$3="", 1, --(Legislations[القطاع]=$A$3))) * (IF($B$3="", 1, --(Legislations[الإدارة]=$B$3))) )} | T3: {=SUMPRODUCT( (--(Legislations[مؤشرات الأداء]="قيد الإجراء")) * (IF($A$3="", 1, --(Legislations[القطاع]=$A$3))) * (IF($B$3="", 1, --(Legislations[الإدارة]=$B$3))) )} | U3: {=SUMPRODUCT( (--(Legislations[مؤشرات الأداء]="في الموعد")) * (IF($A$3="", 1, --(Legislations[القطاع]=$A$3))) * (IF($B$3="", 1, --(Legislations[الإدارة]=$B$3))) )-SUMPRODUCT( (--(Legislations[تجاوز الموعد]="متأخر")) * (IF($A$3="", 1, --(Legislations[القطاع]=$A$3))) * (IF($B$3="", 1, --(Legislations[الإدارة]=$B$3))) )} | V3: {=SUMPRODUCT( (--(Legislations[تجاوز الموعد]="متأخر")) * (IF($A$3="", 1, --(Legislations[القطاع]=$A$3))) * (IF($B$3="", 1, --(Legislations[الإدارة]=$B$3))) )} | W3: {=SUMPRODUCT( (--(Legislations[Late KPI]="متأخر")) * (IF($A$3="", 1, --(Legislations[القطاع]=$A$3))) * (IF($B$3="", 1, --(Legislations[الإدارة]=$B$3))) )} | Y3: {=SUMPRODUCT( --(Special[اسم المشروع]<>"")* IF( $A$3="", 1, --(Special[القطاع]=$A$3) )* IF( $B$3="", 1, --(Special[[الإدارة ]]=$B$3) ) )} | Z3: {=SUMPRODUCT( (--(Special[مشاريع سموه]="نعم")) * (IF($A$3="", 1, --(Special[القطاع]=$A$3))) * (IF($B$3="", 1, --(Special[[الإدارة ]]=$B$3))) )} | AA3: {=SUMPRODUCT( (--(Special[مستوى الإنجاز]="منجز")) * (--(Special[مشاريع سموه]="نعم")) * (IF($A$3="", 1, --(Special[القطاع]=$A$3))) * (IF($B$3="", 1, --(Special[[الإدارة ]]=$B$3))) )} | AB3: {=SUMPRODUCT( (--(Special[مستوى الإنجاز]="متأخر")) * (--(Special[مشاريع سموه]="نعم")) * (IF($A$3="", 1, --(Special[القطاع]=$A$3))) * (IF($B$3="", 1, --(Special[[الإدارة ]]=$B$3))) )} | AC3: {=SUMPRODUCT( (--(Special[مشاريع سموه]="لا")) * (IF($A$3="", 1, --(Special[القطاع]=$A$3))) * (IF($B$3="", 1, --(Special[[الإدارة ]]=$B$3))) )} | AD3: {=SUMPRODUCT( (--(Special[مستوى الإنجاز]="منجز")) * (--(Special[مشاريع سموه]="لا")) * (IF($A$3="", 1, --(Special[القطاع]=$A$3))) * (IF($B$3="", 1, --(Special[[الإدارة ]]=$B$3))) )} | AE3: {=SUMPRODUCT( (--(Special[مستوى الإنجاز]="متأخر")) * (--(Special[مشاريع سموه]="لا")) * (IF($A$3="", 1, --(Special[القطاع]=$A$3))) * (IF($B$3="", 1, --(Special[[الإدارة ]]=$B$3))) )} | AG3: {=SUMPRODUCT( (--(Projects[اسم المشروع]<>"")) * (IF($A$3="", 1, --(Projects[القطاع]=$A$3))) * (IF($B$3="", 1, --(Projects[[الإدارة ]]=$B$3))) )} | AH3: {=SUMPRODUCT( (--(Projects[مستوى الإنجاز]="Active")) * (IF($A$3="", 1, --(Projects[القطاع]=$A$3))) * (IF($B$3="", 1, --(Projects[[الإدارة ]]=$B$3))) )} | AI3: {=SUMPRODUCT( --(((Projects[مستوى الإنجاز]="Cancelled")+ (Projects[مستوى الإنجاز]="Frozen"))>0)* IF($A$3="",1,--(Projects[القطاع]=$A$3))* IF($B$3="",1,--(Projects[[الإدارة ]]=$B$3)) )} | AJ3: {=SUMPRODUCT( (--(Projects[مستوى الإنجاز]="Completed")) * (IF($A$3="", 1, --(Projects[القطاع]=$A$3))) * (IF($B$3="", 1, --(Projects[[الإدارة ]]=$B$3))) )} | AK3: {=SUMPRODUCT( (--(Projects[Late KPI]="Late")) * (IF($A$3="", 1, --(Projects[القطاع]=$A$3))) * (IF($B$3="", 1, --(Projects[[الإدارة ]]=$B$3))) )} | AL3: {=SUMPRODUCT( (--(Projects[الربع]="Q1")) * (IF($A$3="", 1, --(Projects[القطاع]=$A$3))) * (IF($B$3="", 1, --(Projects[[الإدارة ]]=$B$3))) )} | AM3: {=SUMPRODUCT( (--(Projects[الربع]="Q2")) * (IF($A$3="", 1, --(Projects[القطاع]=$A$3))) * (IF($B$3="", 1, --(Projects[[الإدارة ]]=$B$3))) )} | AN3: {=SUMPRODUCT( (--(Projects[الربع]="Q3")) * (IF($A$3="", 1, --(Projects[القطاع]=$A$3))) * (IF($B$3="", 1, --(Projects[[الإدارة ]]=$B$3))) )} | AO3: {=SUMPRODUCT( (--(Projects[الربع]="Q4")) * (IF($A$3="", 1, --(Projects[القطاع]=$A$3))) * (IF($B$3="", 1, --(Projects[[الإدارة ]]=$B$3))) )} | AQ3: {=_xlfn.LET( _xlpm.total, SUMPRODUCT( --(Strategy[المؤشر]<>"")* IF($A$3="",1,--(Strategy[القطاع]=$A$3))* IF($B$3="",1,--(Strategy[الإدارة]=$B$3)) ), IF(_xlpm.total=0,"",_xlpm.total&" / "&$AX$3) )} | AR3: {=_xlfn.LET( _xlpm.results,Strategy[[نتيجة العام ]], _xlpm.include, (Strategy[المؤشر]<>"")* ISNUMBER(_xlpm.results)* (_xlpm.results<>0)* IF($A$3="",1,--(Strategy[القطاع]=$A$3))* IF($B$3="",1,--(Strategy[الإدارة]=$B$3)), IFERROR( AVERAGE(_xlfn._xlws.FILTER(_xlpm.results,_xlpm.include)), "" ) )} | AS3: {=_xlfn.LET( _xlpm.targets,Strategy[المستهدف للعام], _xlpm.include, (Strategy[المؤشر]<>"")* ISNUMBER(_xlpm.targets)* (_xlpm.targets<>0)* IF($A$3="",1,--(Strategy[القطاع]=$A$3))* IF($B$3="",1,--(Strategy[الإدارة]=$B$3)), IFERROR( AVERAGE(_xlfn._xlws.FILTER(_xlpm.targets,_xlpm.include)), "" ) )} | AW3: الشهر الحالي | AX3: {=_xlfn.LET( _xlpm.results,Strategy[[نتيجة العام ]], SUMPRODUCT( --(Strategy[المؤشر]<>"")* --ISNUMBER(_xlpm.results)* --(_xlpm.results<>0)* IF($A$3="",1,--(Strategy[القطاع]=$A$3))* IF($B$3="",1,--(Strategy[الإدارة]=$B$3)) ) )} | AY3: =$AR$3 | AZ3: =$Y$3 | BA3: =$AA$3 | BB3: =$AB$3 | BC3: =$AD$3 | BD3: =$AE$3 | BE3: =$D$3 | BF3: =$I$3 | BG3: =$J$3 | BH3: =$L$3 | BI3: =$N$3 | BJ3: =$O$3 | BK3: =$AG$3 | BL3: =$AJ$3 | BM3: =$AK$3 | BN3: =$S$3 | BO3: =$U$3 | BP3: =$V$3 | BQ3: =$W$3 | BR3: =$AG$6 | BS3: =$AH$6 | BT3: =$AI$6 | BU3: =$AJ$6 | BV3: =$Z$3 | BW3: =$AC$3 | BX3: =BV3-BA3-BB3 | BY3: =BW3-BC3-BD3 | BZ3: =$E$3 | CA3: =$F$3 | CB3: =$H$3 | CC3: =$G$3 | CD3: =$M$3 | CE3: =$AH$3 | CF3: =$AI$3 | CG3: =$AL$3 | CH3: =$AM$3 | CI3: =$AN$3 | CJ3: =$AO$3
AW4: التغيير | AX4: =IF(COUNT(AX2:AX3)<2,"",IF(AX3=AX2,"",IF(AX3>AX2,"▲ +","▼ -")&TEXT(ABS(AX3-AX2),"#,##0"))) | AY4: =IF(OR(AY2="",AY3=""),"",IF(ABS(AY3-AY2)<0.0005,"",IF(AY3>AY2,"▲ +","▼ -")&TEXT(ABS(AY3-AY2)*100,"0.0")&" نقطة مئوية")) | AZ4: =IF(COUNT(AZ2:AZ3)<2,"",IF(AZ3=AZ2,"",IF(AZ3>AZ2,"▲ +","▼ -")&TEXT(ABS(AZ3-AZ2),"#,##0"))) | BA4: =IF(COUNT(BA2:BA3)<2,"",IF(BA3=BA2,"",IF(BA3>BA2,"▲ +","▼ -")&TEXT(ABS(BA3-BA2),"#,##0"))) | BB4: =IF(COUNT(BB2:BB3)<2,"",IF(BB3=BB2,"",IF(BB3>BB2,"▲ +","▼ -")&TEXT(ABS(BB3-BB2),"#,##0"))) | BC4: =IF(COUNT(BC2:BC3)<2,"",IF(BC3=BC2,"",IF(BC3>BC2,"▲ +","▼ -")&TEXT(ABS(BC3-BC2),"#,##0"))) | BD4: =IF(COUNT(BD2:BD3)<2,"",IF(BD3=BD2,"",IF(BD3>BD2,"▲ +","▼ -")&TEXT(ABS(BD3-BD2),"#,##0"))) | BE4: =IF(COUNT(BE2:BE3)<2,"",IF(BE3=BE2,"",IF(BE3>BE2,"▲ +","▼ -")&TEXT(ABS(BE3-BE2),"#,##0"))) | BF4: =IF(COUNT(BF2:BF3)<2,"",IF(BF3=BF2,"",IF(BF3>BF2,"▲ +","▼ -")&TEXT(ABS(BF3-BF2),"#,##0"))) | BG4: =IF(COUNT(BG2:BG3)<2,"",IF(BG3=BG2,"",IF(BG3>BG2,"▲ +","▼ -")&TEXT(ABS(BG3-BG2),"#,##0"))) | ... BQ4: =IF(COUNT(BQ2:BQ3)<2,"",IF(BQ3=BQ2,"",IF(BQ3>BQ2,"▲ +","▼ -")&TEXT(ABS(BQ3-BQ2),"#,##0"))) | BR4: =IF(COUNT(BR2:BR3)<2,"",IF(BR3=BR2,"",IF(BR3>BR2,"+ ▲","- ▼"))) | BS4: =IF(COUNT(BS2:BS3)<2,"",IF(BS3=BS2,"",IF(BS3>BS2,"+ ▲","- ▼"))) | BT4: =IF(COUNT(BT2:BT3)<2,"",IF(BT3=BT2,"",IF(BT3>BT2,"+ ▲","- ▼"))) | BU4: =IF(COUNT(BU2:BU3)<2,"",IF(BU3=BU2,"",IF(BU3>BU2,"+ ▲","- ▼"))) | BV4: =IF(COUNT(BV2:BV3)<2,"",IF(BV3=BV2,"",IF(BV3>BV2,"▲ +","▼ -")&TEXT(ABS(BV3-BV2),"#,##0"))) | BW4: =IF(COUNT(BW2:BW3)<2,"",IF(BW3=BW2,"",IF(BW3>BW2,"▲ +","▼ -")&TEXT(ABS(BW3-BW2),"#,##0"))) | BX4: =IF(COUNT(BX2:BX3)<2,"",IF(BX3=BX2,"",IF(BX3>BX2,"▲ +","▼ -")&TEXT(ABS(BX3-BX2),"#,##0"))) | BY4: =IF(COUNT(BY2:BY3)<2,"",IF(BY3=BY2,"",IF(BY3>BY2,"▲ +","▼ -")&TEXT(ABS(BY3-BY2),"#,##0"))) | BZ4: =IF(COUNT(BZ2:BZ3)<2,"",IF(BZ3=BZ2,"",IF(BZ3>BZ2,"▲ +","▼ -")&TEXT(ABS(BZ3-BZ2),"#,##0"))) | CA4: =IF(COUNT(CA2:CA3)<2,"",IF(CA3=CA2,"",IF(CA3>CA2,"▲ +","▼ -")&TEXT(ABS(CA3-CA2),"#,##0"))) | CB4: =IF(COUNT(CB2:CB3)<2,"",IF(CB3=CB2,"",IF(CB3>CB2,"▲ +","▼ -")&TEXT(ABS(CB3-CB2),"#,##0"))) | CC4: =IF(COUNT(CC2:CC3)<2,"",IF(CC3=CC2,"",IF(CC3>CC2,"▲ +","▼ -")&TEXT(ABS(CC3-CC2),"#,##0"))) | ... CJ4: =IF(COUNT(CJ2:CJ3)<2,"",IF(CJ3=CJ2,"",IF(CJ3>CJ2,"▲ +","▼ -")&TEXT(ABS(CJ3-CJ2),"#,##0")))
A5: القطاع | B5: الادارة | AG5: الموازنة المعتمدة | AH5: المنفق الفعلي | AI5: المخصص | AJ5: غير المخصص | AU5: الأمانة العامة للمجلس التنفيذي | AV5: مكتب الأمين العام | AW5: الشهر السابق | AX5: 0 | AZ5: 0 | BA5: 0 | BB5: 0 | BC5: 0 | BD5: 0 | BE5: 0 | BF5: 0 | BG5: 0 | BH5: 0 | BI5: 0 | BJ5: 0 | BK5: 3 | BL5: 2 | BM5: 0 | BN5: 0 | BO5: 0 | BP5: 0 | BQ5: 0 | BR5: 21756000 | BS5: 15707007 | BT5: 19465555 | BU5: 2290445 | BV5: 0 | BW5: 0 | BX5: 0 | BY5: 0 | BZ5: 0 | CA5: 0 | CB5: 0 | CC5: 0 | CD5: 0 | CE5: 1 | CF5: 0 | CG5: 0 | CH5: 0 | CI5: 0 | CJ5: 3
AG6: {=SUMPRODUCT( IFERROR(--Projects[الموازنة المعتمدة الجديدة],0), --((($A$3="")+(Projects[القطاع]=$A$3))>0), --((($B$3="")+(Projects[[الإدارة ]]=$B$3))>0) )} | AH6: {=SUMPRODUCT( IFERROR(--Projects[المنفق الفعلي],0), --((($A$3="")+(Projects[القطاع]=$A$3))>0), --((($B$3="")+(Projects[[الإدارة ]]=$B$3))>0) )} | AI6: {=SUMPRODUCT( IFERROR(--Projects[المخصص],0), --((($A$3="")+(Projects[القطاع]=$A$3))>0), --((($B$3="")+(Projects[[الإدارة ]]=$B$3))>0) )} | AJ6: {=SUMPRODUCT( IFERROR(--Projects[غير المخصص],0), --((($A$3="")+(Projects[القطاع]=$A$3))>0), --((($B$3="")+(Projects[[الإدارة ]]=$B$3))>0) )} | AU6: الأمانة العامة للمجلس التنفيذي | AV6: مكتب خطة دبي | AW6: الشهر السابق | AX6: 2 | AY6: 1 | AZ6: 6 | BA6: 0 | BB6: 0 | BC6: 1 | BD6: 0 | BE6: 0 | BF6: 0 | BG6: 0 | BH6: 0 | BI6: 0 | BJ6: 0 | BK6: 0 | BL6: 0 | BM6: 0 | BN6: 0 | BO6: 0 | BP6: 0 | BQ6: 0 | BR6: 0 | BS6: 0 | BT6: 0 | BU6: 0 | BV6: 0 | BW6: 6 | BX6: 0 | BY6: 5 | BZ6: 0 | CA6: 0 | CB6: 0 | CC6: 0 | CD6: 0 | CE6: 0 | CF6: 0 | CG6: 0 | CH6: 0 | CI6: 0 | CJ6: 0
A7: {=_xlfn.LET( _xlpm.data, Departments[القطاع], _xlpm.dept, Departments[الوحدة التنظيمية], _xlpm.inc, (IF($B$3="", TRUE, _xlpm.dept=$B$3)) * (_xlpm.data<>""), IFERROR(_xlfn.UNIQUE(_xlfn._xlws.FILTER(_xlpm.data, _xlpm.inc)), "") )} | B7: {=_xlfn.LET( _xlpm.data, Departments[الوحدة التنظيمية], _xlpm.sector, Departments[القطاع], _xlpm.inc, (IF($A$3="", TRUE, _xlpm.sector=$A$3)) * (_xlpm.data<>""), IFERROR(_xlfn.UNIQUE(_xlfn._xlws.FILTER(_xlpm.data, _xlpm.inc)), "") )} | AU7: الأمانة العامة للمجلس التنفيذي | AV7: مكتب التدقيق الداخلي | AW7: الشهر السابق | AX7: 0 | AZ7: 0 | BA7: 0 | BB7: 0 | BC7: 0 | BD7: 0 | BE7: 0 | BF7: 0 | BG7: 0 | BH7: 0 | BI7: 0 | BJ7: 0 | BK7: 1 | BL7: 0 | BM7: 0 | BN7: 1 | BO7: 1 | BP7: 0 | BQ7: 0 | BR7: 846000 | BS7: 40000 | BT7: 846000 | BU7: 0 | BV7: 0 | BW7: 0 | BX7: 0 | BY7: 0 | BZ7: 0 | CA7: 0 | CB7: 0 | CC7: 0 | CD7: 0 | CE7: 1 | CF7: 0 | CG7: 0 | CH7: 0 | CI7: 0 | CJ7: 1
A8: الحوكمة | B8: الشراكات والعلاقات الدولية | D8: م | E8: المواضيع | F8: concate | I8: totals | J8: =SUM(J10:J14) | L8: م | M8: القرارات | N8: concate | P8: totals | Q8: =IF(P10="",0,SUM(_xlfn.CHOOSECOLS(_xlfn.ANCHORARRAY(P10),2))) | S8: م | T8: التشريعات | U8: conacte | Y8: المشاريع | Z8: م | AA8: concate | AB8: totals | AC8: =SUM(AC10:AC13) | AG8: المشاريع | AH8: م | AI8: concate | AK8: totals | AL8: =SUM(AL10:AL15) | AU8: الأمانة العامة للمجلس التنفيذي | AV8: الأبحاث والرصد | AW8: الشهر السابق | AX8: 1 | AY8: 0.53763441 | AZ8: 0 | BA8: 0 | BB8: 0 | BC8: 0 | BD8: 0 | BE8: 0 | BF8: 0 | BG8: 0 | BH8: 0 | BI8: 0 | BJ8: 0 | BK8: 3 | BL8: 0 | BM8: 0 | BN8: 0 | BO8: 0 | BP8: 0 | BQ8: 0 | BR8: 2000000 | BS8: 29497 | BT8: 1166043 | BU8: 833957 | BV8: 0 | BW8: 0 | BX8: 0 | BY8: 0 | BZ8: 0 | CA8: 0 | CB8: 0 | CC8: 0 | CD8: 0 | CE8: 3 | CF8: 0 | CG8: 0 | CH8: 0 | CI8: 0 | CJ8: 0
A9: التنمية المستدامة | B9: مكتب التدقيق الداخلي | AU9: الأمانة العامة للمجلس التنفيذي | AV9: الشراكات والعلاقات الدولية | AW9: الشهر السابق | AX9: 0 | AZ9: 0 | BA9: 0 | BB9: 0 | BC9: 0 | BD9: 0 | BE9: 0 | BF9: 0 | BG9: 0 | BH9: 0 | BI9: 0 | BJ9: 0 | BK9: 0 | BL9: 0 | BM9: 0 | BN9: 0 | BO9: 0 | BP9: 0 | BQ9: 0 | BR9: 0 | BS9: 0 | BT9: 0 | BU9: 0 | BV9: 0 | BW9: 0 | BX9: 0 | BY9: 0 | BZ9: 0 | CA9: 0 | CB9: 0 | CC9: 0 | CD9: 0 | CE9: 0 | CF9: 0 | CG9: 0 | CH9: 0 | CI9: 0 | CJ9: 0
A10: الاقتصاد والتنمية الاجتماعية | B10: مكتب خطة دبي | D10: =IF(E10="","",1+D9) | E10: {=_xlfn._xlws.FILTER( ECSAC[[الموضوع ]]& IF( ECSAC[ملاحظات فريق الأمانة العامة]="", "", " - "&ECSAC[ملاحظات فريق الأمانة العامة] ), (ECSAC[[الموضوع ]]<>"")* (ECSAC[مستوى الإنجاز]="متأخر")* IF( $A$3="", 1, --(ECSAC[القطاع]=$A$3) )* IF( $B$3="", 1, --(ECSAC[الإدارة]=$B$3) ), "" )} | F10: =IF(D10="","",CONCATENATE(D10,". ",E10)) | I10: {=_xlfn.LET( _xlpm.Status,ECSAC[مستوى الإنجاز], _xlpm.Sector,ECSAC[القطاع], _xlpm.Department,ECSAC[الإدارة], _xlpm.Criteria, (_xlpm.Status<>"")* IF($A$3="",1,--(_xlpm.Sector=$A$3))* IF($B$3="",1,--(_xlpm.Department=$B$3)), _xlpm.Types,_xlfn.UNIQUE(_xlfn._xlws.FILTER(_xlpm.Status,_xlpm.Criteria,"")), _xlpm.Counts, IF( $A$3="", IF( $B$3="", COUNTIFS(_xlpm.Status,_xlpm.Types), COUNTIFS(_xlpm.Status,_xlpm.Types,_xlpm.Department,$B$3) ), IF( $B$3="", COUNTIFS(_xlpm.Status,_xlpm.Types,_xlpm.Sector,$A$3), COUNTIFS(_xlpm.Status,_xlpm.Types,_xlpm.Sector,$A$3,_xlpm.Department,$B$3) ) ), IF(_xlpm.Types="","",_xlfn.HSTACK(_xlpm.Types,_xlpm.Counts)) )} | J10: 16 | L10: =IF(M10="","",1+L9) | M10: {=_xlfn._xlws.FILTER( Resolutions[الموضوع]&" - "&Resolutions[ملاحظات], (Resolutions[الموضوع]<>"")* ( ( (TRIM(SUBSTITUTE(Resolutions[متطلبات المتابعة],CHAR(160)," "))="رسالة رسمية")+ (TRIM(SUBSTITUTE(Resolutions[متطلبات المتابعة],CHAR(160)," "))="بريد من الوحدة التنظيمية") )>0 )* (TRIM(SUBSTITUTE(Resolutions[مستوى الإنجاز],CHAR(160)," "))="متأخر")* IF( $A$3="", 1, --(TRIM(SUBSTITUTE(Resolutions[القطاع],CHAR(160)," "))=TRIM(SUBSTITUTE($A$3,CHAR(160)," "))) )* IF( $B$3="", 1, --(TRIM(SUBSTITUTE(Resolutions[الإدارة],CHAR(160)," "))=TRIM(SUBSTITUTE($B$3,CHAR(160)," "))) ), "" )} | N10: =IF(L10="","",CONCATENATE(L10,". ",M10)) | P10: {=_xlfn.LET( _xlpm.tidy,_xlfn.LAMBDA(_xlpm.x, TRIM(SUBSTITUTE(IFERROR(_xlpm.x&"",""),CHAR(160)," ")) ), _xlpm.topic,IFERROR(Resolutions[الموضوع],""), _xlpm.followup,_xlpm.tidy(Resolutions[متطلبات المتابعة]), _xlpm.rawStatus,_xlpm.tidy(Resolutions[مستوى الإنجاز]), _xlpm.status,IF(_xlpm.rawStatus="","غير محدد",_xlpm.rawStatus), _xlpm.sector,_xlpm.tidy(Resolutions[القطاع]), _xlpm.dept,_xlpm.tidy(Resolutions[الإدارة]), _xlpm.selectedSector,_xlpm.tidy($A$3), _xlpm.selectedDept,_xlpm.tidy($B$3), _xlpm.include, (_xlpm.topic<>"")* ( ( (_xlpm.followup="رسالة رسمية")+ (_xlpm.followup="بريد من الوحدة التنظيمية") )>0 )* IF(_xlpm.selectedSector="",1,--(_xlpm.sector=_xlpm.selectedSector))* IF(_xlpm.selectedDept="",1,--(_xlpm.dept=_xlpm.selectedDept)), IF( SUM(_xlpm.include)=0, "", _xlfn.LET( _xlpm.filteredStatus,_xlfn._xlws.FILTER(_xlpm.status,_xlpm.include), _xlpm.types,_xlfn.UNIQUE(_xlpm.filteredStatus), _xlpm.counts,_xlfn.MAP( _xlpm.types, _xlfn.LAMBDA(_xlpm.itemStatus, SUM(--(_xlpm.filteredStatus=_xlpm.itemStatus)) ) ), _xlfn.HSTACK(_xlpm.types,_xlpm.counts) ) ) )} | Q10: 38 | S10: =IF(T10="","",1+S9) | T10: {=_xlfn._xlws.FILTER( Legislations[[عنوان التشريع ]]& IF( Legislations[[مستجدات ]]="", "", " - "&Legislations[[مستجدات ]] ), (Legislations[[عنوان التشريع ]]<>"")* (Legislations[Late KPI]="متأخر")* IF( $A$3="", 1, --(Legislations[القطاع]=$A$3) )* IF( $B$3="", 1, --(Legislations[الإدارة]=$B$3) ), "" )} | U10: =IF(S10="","",CONCATENATE(S10,". ",T10)) | Y10: {=_xlfn._xlws.FILTER( Special[اسم المشروع]&" - "&Special[ملاحظات مدير المشروع], (Special[مستوى الإنجاز]="متأخر")* IF( $B$3="", IF( $A$3="", TRUE, Special[القطاع]=$A$3 ), IF( $A$3="", Special[[الإدارة ]]=$B$3, (Special[[الإدارة ]]=$B$3)* (Special[القطاع]=$A$3) ) ), "" )} | Z10: =IF(Y10="","",1+Z9) | AA10: =IF(Z10="","",CONCATENATE(Z10,". ",Y10)) | AB10: {=_xlfn.LET( _xlpm.Status,Special[مستوى الإنجاز], _xlpm.Sector,Special[القطاع], _xlpm.Department,Special[[الإدارة ]], _xlpm.Criteria, (_xlpm.Status<>"")* IF($A$3="",1,--(_xlpm.Sector=$A$3))* IF($B$3="",1,--(_xlpm.Department=$B$3)), _xlpm.Types,_xlfn.UNIQUE(_xlfn._xlws.FILTER(_xlpm.Status,_xlpm.Criteria,"")), _xlpm.Counts, IF( $A$3="", IF( $B$3="", COUNTIFS(_xlpm.Status,_xlpm.Types), COUNTIFS(_xlpm.Status,_xlpm.Types,_xlpm.Department,$B$3) ), IF( $B$3="", COUNTIFS(_xlpm.Status,_xlpm.Types,_xlpm.Sector,$A$3), COUNTIFS(_xlpm.Status,_xlpm.Types,_xlpm.Sector,$A$3,_xlpm.Department,$B$3) ) ), IF(_xlpm.Types="","",_xlfn.HSTACK(_xlpm.Types,_xlpm.Counts)) )} | AC10: 23 | AG10: {=_xlfn._xlws.FILTER( Projects[ملاحظات مدير المشروع]&" - "&Projects[اسم المشروع], (Projects[اسم المشروع]<>"")* ( ( (Projects[Late KPI]="Late")+ (Projects[مستوى الإنجاز]="Frozen")+ (Projects[مستوى الإنجاز]="Cancelled")+ (Projects[مستوى الإنجاز]="Transferred") )>0 )* IF( $A$3="", 1, --(Projects[القطاع]=$A$3) )* IF( $B$3="", 1, --(Projects[[الإدارة ]]=$B$3) ), "" )} | AH10: =IF(AG10="","",1+AH9) | AI10: =IF(AH10="","",CONCATENATE(AH10,". ",AG10)) | AK10: {=_xlfn.LET( _xlpm.Status,Projects[مستوى الإنجاز], _xlpm.Sector,Projects[القطاع], _xlpm.Department,Projects[[الإدارة ]], _xlpm.Criteria, (_xlpm.Status<>"")* IF($A$3="",1,--(_xlpm.Sector=$A$3))* IF($B$3="",1,--(_xlpm.Department=$B$3)), _xlpm.Types,_xlfn.UNIQUE(_xlfn._xlws.FILTER(_xlpm.Status,_xlpm.Criteria,"")), _xlpm.Counts, IF( $A$3="", IF( $B$3="", COUNTIFS(_xlpm.Status,_xlpm.Types), COUNTIFS(_xlpm.Status,_xlpm.Types,_xlpm.Department,$B$3) ), IF( $B$3="", COUNTIFS(_xlpm.Status,_xlpm.Types,_xlpm.Sector,$A$3), COUNTIFS(_xlpm.Status,_xlpm.Types,_xlpm.Sector,$A$3,_xlpm.Department,$B$3) ) ), IF(_xlpm.Types="","",_xlfn.HSTACK(_xlpm.Types,_xlpm.Counts)) )} | AL10: 61 | AU10: الاقتصاد والتنمية الاجتماعية | AV10: السياسات والإستراتيجيات الاقتصادية | AW10: الشهر السابق | AX10: 0 | AZ10: 7 | BA10: 4 | BB10: 0 | BC10: 1 | BD10: 0 | BE10: 17 | BF10: 10 | BG10: 1 | BH10: 8 | BI10: 7 | BJ10: 0 | BK10: 0 | BL10: 0 | BM10: 0 | BN10: 33 | BO10: 24 | BP10: 9 | BQ10: 0 | BR10: 0 | BS10: 0 | BT10: 0 | BU10: 0 | BV10: 6 | BW10: 1 | BX10: 2 | BY10: 0 | BZ10: 11 | CA10: 6 | CB10: 2 | CC10: 4 | CD10: 1 | CE10: 0 | CF10: 0 | CG10: 0 | CH10: 0 | CI10: 0 | CJ10: 0
A11: التميز والخدمات الحكومية | B11: الأبحاث والرصد | D11: =IF(E11="","",1+D10) | F11: =IF(D11="","",CONCATENATE(D11,". ",E11)) | I11: منجز | J11: 43 | L11: =IF(M11="","",1+L10) | N11: =IF(L11="","",CONCATENATE(L11,". ",M11)) | P11: قيد التطوير | Q11: 26 | S11: =IF(T11="","",1+S10) | U11: =IF(S11="","",CONCATENATE(S11,". ",T11)) | Z11: =IF(Y11="","",1+Z10) | AA11: =IF(Z11="","",CONCATENATE(Z11,". ",Y11)) | AB11: قيد المراجعة | AC11: 3 | AH11: =IF(AG11="","",1+AH10) | AI11: =IF(AH11="","",CONCATENATE(AH11,". ",AG11)) | AK11: Frozen | AL11: 3 | AU11: الاقتصاد والتنمية الاجتماعية | AV11: السياسات والإستراتيجيات الاجتماعية | AW11: الشهر السابق | AX11: 0 | AZ11: 17 | BA11: 4 | BB11: 0 | BC11: 2 | BD11: 0 | BE11: 23 | BF11: 6 | BG11: 3 | BH11: 14 | BI11: 12 | BJ11: 0 | BK11: 4 | BL11: 1 | BM11: 0 | BN11: 28 | BO11: 23 | BP11: 5 | BQ11: 0 | BR11: 912500 | BS11: 0 | BT11: 290000 | BU11: 622500 | BV11: 9 | BW11: 8 | BX11: 5 | BY11: 6 | BZ11: 21 | CA11: 2 | CB11: 14 | CC11: 0 | CD11: 1 | CE11: 1 | CF11: 0 | CG11: 0 | CH11: 0 | CI11: 0 | CJ11: 4
A12: الاتصال الحكومي وشؤون الأمانة العامة | B12: الحوكمة | D12: =IF(E12="","",1+D11) | F12: =IF(D12="","",CONCATENATE(D12,". ",E12)) | I12: قيد التطوير | J12: 52 | L12: =IF(M12="","",1+L11) | N12: =IF(L12="","",CONCATENATE(L12,". ",M12)) | P12: قيد المراجعة | Q12: 5 | S12: =IF(T12="","",1+S11) | U12: =IF(S12="","",CONCATENATE(S12,". ",T12)) | Z12: =IF(Y12="","",1+Z11) | AA12: =IF(Z12="","",CONCATENATE(Z12,". ",Y12)) | AB12: قيد التطوير | AC12: 35 | AH12: =IF(AG12="","",1+AH11) | AI12: =IF(AH12="","",CONCATENATE(AH12,". ",AG12)) | AK12: Completed | AL12: 10 | AU12: الاقتصاد والتنمية الاجتماعية | AW12: الشهر السابق | AX12: 0 | AZ12: 0 | BA12: 0 | BB12: 0 | BC12: 0 | BD12: 0 | BE12: 0 | BF12: 0 | BG12: 0 | BH12: 0 | BI12: 0 | BJ12: 0 | BK12: 2 | BL12: 0 | BM12: 0 | BN12: 0 | BO12: 0 | BP12: 0 | BQ12: 0 | BR12: 772000 | BS12: 36942 | BT12: 272000 | BU12: 500000 | BV12: 0 | BW12: 0 | BX12: 0 | BY12: 0 | BZ12: 0 | CA12: 0 | CB12: 0 | CC12: 0 | CD12: 0 | CE12: 2 | CF12: 0 | CG12: 0 | CH12: 0 | CI12: 0 | CJ12: 2
B13: التشريعات الحكومية | D13: =IF(E13="","",1+D12) | F13: =IF(D13="","",CONCATENATE(D13,". ",E13)) | I13: قيد المراجعة | J13: 6 | L13: =IF(M13="","",1+L12) | N13: =IF(L13="","",CONCATENATE(L13,". ",M13)) | P13: غير محدد | Q13: 1 | S13: =IF(T13="","",1+S12) | U13: =IF(S13="","",CONCATENATE(S13,". ",T13)) | Z13: =IF(Y13="","",1+Z12) | AA13: =IF(Z13="","",CONCATENATE(Z13,". ",Y13)) | AH13: =IF(AG13="","",1+AH12) | AI13: =IF(AH13="","",CONCATENATE(AH13,". ",AG13)) | AK13: Not Started | AL13: 7 | AU13: التميز والخدمات الحكومية | AV13: التميز والخدمات الحكومية | AW13: الشهر السابق | AX13: 2 | AY13: 0.95833333 | AZ13: 0 | BA13: 0 | BB13: 0 | BC13: 0 | BD13: 0 | BE13: 0 | BF13: 0 | BG13: 0 | BH13: 0 | BI13: 0 | BJ13: 0 | BK13: 8 | BL13: 0 | BM13: 0 | BN13: 1 | BO13: 1 | BP13: 0 | BQ13: 0 | BR13: 5370000 | BS13: 704044 | BT13: 1826903 | BU13: 3543097 | BV13: 0 | BW13: 0 | BX13: 0 | BY13: 0 | BZ13: 0 | CA13: 0 | CB13: 0 | CC13: 0 | CD13: 0 | CE13: 8 | CF13: 0 | CG13: 0 | CH13: 0 | CI13: 0 | CJ13: 8
B14: التنفيذ والأداء | D14: =IF(E14="","",1+D13) | F14: =IF(D14="","",CONCATENATE(D14,". ",E14)) | L14: =IF(M14="","",1+L13) | N14: =IF(L14="","",CONCATENATE(L14,". ",M14)) | S14: =IF(T14="","",1+S13) | U14: =IF(S14="","",CONCATENATE(S14,". ",T14)) | Z14: =IF(Y14="","",1+Z13) | AA14: =IF(Z14="","",CONCATENATE(Z14,". ",Y14)) | AH14: =IF(AG14="","",1+AH13) | AI14: =IF(AH14="","",CONCATENATE(AH14,". ",AG14)) | AK14: Transferred | AL14: 2 | AU14: التميز والخدمات الحكومية | AV14: التقييم والدراسات | AW14: الشهر السابق | AX14: 0 | AZ14: 0 | BA14: 0 | BB14: 0 | BC14: 0 | BD14: 0 | BE14: 0 | BF14: 0 | BG14: 0 | BH14: 0 | BI14: 0 | BJ14: 0 | BK14: 12 | BL14: 2 | BM14: 0 | BN14: 0 | BO14: 0 | BP14: 0 | BQ14: 0 | BR14: 15480000 | BS14: 2311904 | BT14: 6312921 | BU14: 9167079 | BV14: 0 | BW14: 0 | BX14: 0 | BY14: 0 | BZ14: 0 | CA14: 0 | CB14: 0 | CC14: 0 | CD14: 0 | CE14: 9 | CF14: 1 | CG14: 0 | CH14: 1 | CI14: 0 | CJ14: 11
B15: السياسات والاستراتيجيات الصحية والعدل | D15: =IF(E15="","",1+D14) | F15: =IF(D15="","",CONCATENATE(D15,". ",E15)) | L15: =IF(M15="","",1+L14) | N15: =IF(L15="","",CONCATENATE(L15,". ",M15)) | S15: =IF(T15="","",1+S14) | U15: =IF(S15="","",CONCATENATE(S15,". ",T15)) | Z15: =IF(Y15="","",1+Z14) | AA15: =IF(Z15="","",CONCATENATE(Z15,". ",Y15)) | AH15: =IF(AG15="","",1+AH14) | AI15: =IF(AH15="","",CONCATENATE(AH15,". ",AG15)) | AK15: Cancelled | AL15: 1 | AU15: التميز والخدمات الحكومية | AW15: الشهر السابق | AX15: 0 | AZ15: 3 | BA15: 2 | BB15: 0 | BC15: 0 | BD15: 0 | BE15: 0 | BF15: 0 | BG15: 0 | BH15: 0 | BI15: 0 | BJ15: 0 | BK15: 6 | BL15: 0 | BM15: 0 | BN15: 0 | BO15: 0 | BP15: 0 | BQ15: 0 | BR15: 3150000 | BS15: 971014 | BT15: 2019572 | BU15: 1130428 | BV15: 2 | BW15: 1 | BX15: 0 | BY15: 1 | BZ15: 0 | CA15: 0 | CB15: 0 | CC15: 0 | CD15: 0 | CE15: 6 | CF15: 0 | CG15: 0 | CH15: 0 | CI15: 0 | CJ15: 6
B16: السياسات والاستراتيجيات البيئية والبنية التحتية | D16: =IF(E16="","",1+D15) | F16: =IF(D16="","",CONCATENATE(D16,". ",E16)) | L16: =IF(M16="","",1+L15) | N16: =IF(L16="","",CONCATENATE(L16,". ",M16)) | S16: =IF(T16="","",1+S15) | U16: =IF(S16="","",CONCATENATE(S16,". ",T16)) | Z16: =IF(Y16="","",1+Z15) | AA16: =IF(Z16="","",CONCATENATE(Z16,". ",Y16)) | AH16: =IF(AG16="","",1+AH15) | AI16: =IF(AH16="","",CONCATENATE(AH16,". ",AG16)) | AU16: التنمية المستدامة | AV16: السياسات والاستراتيجيات البيئية والبنية التحتية | AW16: الشهر السابق | AX16: 0 | AZ16: 10 | BA16: 1 | BB16: 0 | BC16: 2 | BD16: 1 | BE16: 39 | BF16: 10 | BG16: 1 | BH16: 23 | BI16: 14 | BJ16: 0 | BK16: 0 | BL16: 0 | BM16: 0 | BN16: 30 | BO16: 30 | BP16: 0 | BQ16: 0 | BR16: 0 | BS16: 0 | BT16: 0 | BU16: 0 | BV16: 6 | BW16: 4 | BX16: 5 | BY16: 1 | BZ16: 35 | CA16: 4 | CB16: 21 | CC16: 7 | CD16: 9 | CE16: 0 | CF16: 0 | CG16: 0 | CH16: 0 | CI16: 0 | CJ16: 0
